2023-02-23 08:21:55,823 ERROR Error in plot_travis_volume_since_1943
Traceback (most recent call last):
  File "C:\Users\BTHAMAN\Documents\usgs_lake_levels\res.volume.1943.lcragage.py", line 37, in plot_travis_volume_since_1943
    x, y, full, header, latest_vals = lcra.import_gage_data(site_num='3963', full_level=681.0)
  File "C:\Users\BTHAMAN\Documents\usgs_lake_levels\lcra_gage_selenium.py", line 80, in import_gage_data
    browser = webdriver.Chrome(chrome_options=options)
  File "C:\Users\BTHAMAN\Documents\usgs_lake_levels\env\lib\site-packages\selenium\webdriver\chrome\webdriver.py", line 73, in __init__
    self.service.start()
  File "C:\Users\BTHAMAN\Documents\usgs_lake_levels\env\lib\site-packages\selenium\webdriver\common\service.py", line 72, in start
    self.process = subprocess.Popen(cmd, env=self.env,
  File "C:\Users\BTHAMAN\AppData\Local\Programs\Python\Python39\lib\subprocess.py", line 951, in __init__
    self._execute_child(args, executable, preexec_fn, close_fds,
  File "C:\Users\BTHAMAN\AppData\Local\Programs\Python\Python39\lib\subprocess.py", line 1420, in _execute_child
    hp, ht, pid, tid = _winapi.CreateProcess(executable, args,
OSError: [WinError 1260] This program is blocked by group policy. For more information, contact your system administrator
2023-02-23 13:09:16,163 ERROR Error in plot_travis_volume_since_1943
Traceback (most recent call last):
  File "C:\Users\BTHAMAN\Documents\usgs_lake_levels\res.volume.1943.lcragage.py", line 38, in plot_travis_volume_since_1943
    x, y, full, header, latest_vals = lcra.import_gage_data(site_num='3963', full_level=681.0)
  File "C:\Users\BTHAMAN\Documents\usgs_lake_levels\lcra_gage_selenium.py", line 80, in import_gage_data
    browser = webdriver.Chrome(chrome_options=options)
  File "C:\Users\BTHAMAN\Documents\usgs_lake_levels\env\lib\site-packages\selenium\webdriver\chrome\webdriver.py", line 73, in __init__
    self.service.start()
  File "C:\Users\BTHAMAN\Documents\usgs_lake_levels\env\lib\site-packages\selenium\webdriver\common\service.py", line 72, in start
    self.process = subprocess.Popen(cmd, env=self.env,
  File "C:\Users\BTHAMAN\AppData\Local\Programs\Python\Python39\lib\subprocess.py", line 951, in __init__
    self._execute_child(args, executable, preexec_fn, close_fds,
  File "C:\Users\BTHAMAN\AppData\Local\Programs\Python\Python39\lib\subprocess.py", line 1420, in _execute_child
    hp, ht, pid, tid = _winapi.CreateProcess(executable, args,
OSError: [WinError 1260] This program is blocked by group policy. For more information, contact your system administrator
2023-02-23 13:09:41,178 ERROR Error in plot_travis_volume_since_1943
Traceback (most recent call last):
  File "C:\Users\BTHAMAN\Documents\usgs_lake_levels\res.volume.1943.lcragage.py", line 38, in plot_travis_volume_since_1943
    x, y, full, header, latest_vals = lcra.import_gage_data(site_num='3963', full_level=681.0)
  File "C:\Users\BTHAMAN\Documents\usgs_lake_levels\lcra_gage_selenium.py", line 80, in import_gage_data
    browser = webdriver.Chrome(chrome_options=options)
  File "C:\Users\BTHAMAN\Documents\usgs_lake_levels\env\lib\site-packages\selenium\webdriver\chrome\webdriver.py", line 73, in __init__
    self.service.start()
  File "C:\Users\BTHAMAN\Documents\usgs_lake_levels\env\lib\site-packages\selenium\webdriver\common\service.py", line 72, in start
    self.process = subprocess.Popen(cmd, env=self.env,
  File "C:\Users\BTHAMAN\AppData\Local\Programs\Python\Python39\lib\subprocess.py", line 951, in __init__
    self._execute_child(args, executable, preexec_fn, close_fds,
  File "C:\Users\BTHAMAN\AppData\Local\Programs\Python\Python39\lib\subprocess.py", line 1420, in _execute_child
    hp, ht, pid, tid = _winapi.CreateProcess(executable, args,
OSError: [WinError 1260] This program is blocked by group policy. For more information, contact your system administrator
2023-04-01 09:14:13,226 ERROR Error in plot_travis_volume_since_1943
Traceback (most recent call last):
  File "C:\Users\BTHAMAN\Documents\usgs_lake_levels\res.volume.1943.lcragage.py", line 38, in plot_travis_volume_since_1943
    x, y, full, header, latest_vals = lcra.import_gage_data(site_num='3963', full_level=681.0)
TypeError: cannot unpack non-iterable NoneType object
2023-04-19 08:00:55,398 ERROR Error in plot_travis_volume_since_1943
Traceback (most recent call last):
  File "C:\Users\BTHAMAN\Documents\usgs_lake_levels\res.volume.1943.lcragage.py", line 38, in plot_travis_volume_since_1943
    x, y, full, header, latest_vals = lcra.import_gage_data(site_num='3963', full_level=681.0)
  File "C:\Users\BTHAMAN\Documents\usgs_lake_levels\lcra_gage_selenium.py", line 80, in import_gage_data
    browser = webdriver.Chrome(chrome_options=options)
  File "C:\Users\BTHAMAN\Documents\usgs_lake_levels\env\lib\site-packages\selenium\webdriver\chrome\webdriver.py", line 76, in __init__
    RemoteWebDriver.__init__(
  File "C:\Users\BTHAMAN\Documents\usgs_lake_levels\env\lib\site-packages\selenium\webdriver\remote\webdriver.py", line 157, in __init__
    self.start_session(capabilities, browser_profile)
  File "C:\Users\BTHAMAN\Documents\usgs_lake_levels\env\lib\site-packages\selenium\webdriver\remote\webdriver.py", line 252, in start_session
    response = self.execute(Command.NEW_SESSION, parameters)
  File "C:\Users\BTHAMAN\Documents\usgs_lake_levels\env\lib\site-packages\selenium\webdriver\remote\webdriver.py", line 321, in execute
    self.error_handler.check_response(response)
  File "C:\Users\BTHAMAN\Documents\usgs_lake_levels\env\lib\site-packages\selenium\webdriver\remote\errorhandler.py", line 242, in check_response
    raise exception_class(message, screen, stacktrace)
selenium.common.exceptions.SessionNotCreatedException: Message: session not created: This version of ChromeDriver only supports Chrome version 110
Current browser version is 112.0.5615.121 with binary path C:\Program Files\Google\Chrome\Application\chrome.exe
  (Driver info: chromedriver=110.0.5481.77 (65ed616c6e8ee3fe0ad64fe83796c020644d42af-refs/branch-heads/5481@{#839}),platform=Windows NT 10.0.19044 x86_64)

